Workbook

Sheet Dashboard
A1: EĞİTİM DASHBOARD
A2: Ocak – Temmuz 2026 · 46 eğitim faaliyeti · Kaynak: Eğitim takip tablosu
A4: TOPLAM EĞİTİM | C4: YENİ EĞİTİM | E4: TOPLAM KATILIMCI | G4: TOPLAM SERTİFİKA | I4: ORT. DEĞERLENDİRME | K4: TOPLAM EĞİTİM GÜNÜ
A5: =COUNTA(Veri!$B$2:$B$47) -> 46 | C5: =COUNTIF(Veri!$A$2:$A$47,"YENİ") -> 22 | E5: =SUM(Veri!$J$2:$J$47) -> 1218 | G5: =SUM(Veri!$K$2:$K$47) -> 1218 | I5: =AVERAGE(Veri!$G$2:$G$47) -> 4.0190323 | K5: =SUM(Veri!$C$2:$C$47) -> 93
A6: =COUNTIF(Veri!$A$2:$A$47,"PLANLI")&" planlı, "&COUNTIF(Veri!$A$2:$A$47,"YENİ")&" yeni" -> 24 planlı, 22 yeni | C6: =TEXT(COUNTIF(Veri!$A$2:$A$47,"YENİ")/COUNTA(Veri!$B$2:$B$47),"0%")&" toplam içinde" -> 48% toplam içinde | E6: =TEXT(SUM(Veri!$J$2:$J$47)/COUNTA(Veri!$B$2:$B$47),"0")&" ort. / eğitim" -> 26 ort. / eğitim | G6: "Katılımcı başı 1 sertifika" | I6: =COUNT(Veri!$G$2:$G$47)&" eğitimde anket verisi var" -> 31 eğitimde anket verisi var | K6: ="Eğitim başına ort. "&TEXT(SUM(Veri!$C$2:$C$47)/COUNTA(Veri!$B$2:$B$47),"0")&" gün" -> Eğitim başına ort. 2 gün
A8: AYLIK TREND
A10: Ay | B10: Ay No | C10: Eğitim Sayısı | D10: Katılımcı Sayısı
A11: Ocak | B11: 1 | C11: =COUNTIFS(Veri!$E$2:$E$47,$B11) -> 4 | D11: =SUMIFS(Veri!$J$2:$J$47,Veri!$E$2:$E$47,$B11) -> 100
A12: Şubat | B12: 2 | C12: =COUNTIFS(Veri!$E$2:$E$47,$B12) -> 5 | D12: =SUMIFS(Veri!$J$2:$J$47,Veri!$E$2:$E$47,$B12) -> 90
A13: Mart | B13: 3 | C13: =COUNTIFS(Veri!$E$2:$E$47,$B13) -> 4 | D13: =SUMIFS(Veri!$J$2:$J$47,Veri!$E$2:$E$47,$B13) -> 230
A14: Nisan | B14: 4 | C14: =COUNTIFS(Veri!$E$2:$E$47,$B14) -> 12 | D14: =SUMIFS(Veri!$J$2:$J$47,Veri!$E$2:$E$47,$B14) -> 430
A15: Mayıs | B15: 5 | C15: =COUNTIFS(Veri!$E$2:$E$47,$B15) -> 11 | D15: =SUMIFS(Veri!$J$2:$J$47,Veri!$E$2:$E$47,$B15) -> 234
A16: Haziran | B16: 6 | C16: =COUNTIFS(Veri!$E$2:$E$47,$B16) -> 7 | D16: =SUMIFS(Veri!$J$2:$J$47,Veri!$E$2:$E$47,$B16) -> 51
A17: Temmuz | B17: 7 | C17: =COUNTIFS(Veri!$E$2:$E$47,$B17) -> 3 | D17: =SUMIFS(Veri!$J$2:$J$47,Veri!$E$2:$E$47,$B17) -> 83
A27: EĞİTİM PROFİLİ
A29: Eğitim Tipi | B29: Eğitim Sayısı | C29: Katılımcı Sayısı | F29: Eğitim Durumu | G29: Eğitim Sayısı | H29: Katılımcı Sayısı
A30: ÇEVRİM İÇİ | B30: =COUNTIF(Veri!$F$2:$F$47,$A30) -> 14 | C30: =SUMIF(Veri!$F$2:$F$47,$A30,Veri!$J$2:$J$47) -> 733 | F30: PLANLI | G30: =COUNTIF(Veri!$A$2:$A$47,$F30) -> 24 | H30: =SUMIF(Veri!$A$2:$A$47,$F30,Veri!$J$2:$J$47) -> 500
A31: SINIF İÇİ | B31: =COUNTIF(Veri!$F$2:$F$47,$A31) -> 32 | C31: =SUMIF(Veri!$F$2:$F$47,$A31,Veri!$J$2:$J$47) -> 485 | F31: YENİ | G31: =COUNTIF(Veri!$A$2:$A$47,$F31) -> 22 | H31: =SUMIF(Veri!$A$2:$A$47,$F31,Veri!$J$2:$J$47) -> 718
A46: EN ÇOK KATILIM ALAN 10 EĞİTİM
A48: Eğitim Adı | B48: Katılan Kişi Sayısı
A49: =INDEX(Veri!$B$2:$B$47,MATCH(1,Veri!$L$2:$L$47,0)) -> Yeşil Hidrojen ve Çimento Sektörü Webinar Serisi I | B49: =INDEX(Veri!$J$2:$J$47,MATCH(1,Veri!$L$2:$L$47,0)) -> 187
A50: =INDEX(Veri!$B$2:$B$47,MATCH(2,Veri!$L$2:$L$47,0)) -> Yeşil Hidrojen ve Çimento Sektörü Webinar Serisi II | B50: =INDEX(Veri!$J$2:$J$47,MATCH(2,Veri!$L$2:$L$47,0)) -> 138
A51: =INDEX(Veri!$B$2:$B$47,MATCH(3,Veri!$L$2:$L$47,0)) -> Düşük Karbon Yolunda Yeni Nesil Çimentolar Zirvesi | B51: =INDEX(Veri!$J$2:$J$47,MATCH(3,Veri!$L$2:$L$47,0)) -> 83
A52: =INDEX(Veri!$B$2:$B$47,MATCH(4,Veri!$L$2:$L$47,0)) -> Yeşil Hidrojen ve Çimento Sektörü Webinar Serisi III | B52: =INDEX(Veri!$J$2:$J$47,MATCH(4,Veri!$L$2:$L$47,0)) -> 82
A53: =INDEX(Veri!$B$2:$B$47,MATCH(5,Veri!$L$2:$L$47,0)) -> Sürdürülebilir ve Sorumlu Tedarik Zinciri Yönetimi Eğitimi (Oyak Çimento) | B53: =INDEX(Veri!$J$2:$J$47,MATCH(5,Veri!$L$2:$L$47,0)) -> 76
A54: =INDEX(Veri!$B$2:$B$47,MATCH(6,Veri!$L$2:$L$47,0)) -> Yeni Mühendisler için Enerji Verimliliği Eğitimi | B54: =INDEX(Veri!$J$2:$J$47,MATCH(6,Veri!$L$2:$L$47,0)) -> 40
A55: =INDEX(Veri!$B$2:$B$47,MATCH(7,Veri!$L$2:$L$47,0)) -> Sürdürülebilir Tedarik Zinciri Yönetimi Eğitimi | B55: =INDEX(Veri!$J$2:$J$47,MATCH(7,Veri!$L$2:$L$47,0)) -> 40
A56: =INDEX(Veri!$B$2:$B$47,MATCH(8,Veri!$L$2:$L$47,0)) -> Çimento Sektörü Özelinde Sınırda Karbon Düzenleme Mekanizması Eğitimi | B56: =INDEX(Veri!$J$2:$J$47,MATCH(8,Veri!$L$2:$L$47,0)) -> 37
A57: =INDEX(Veri!$B$2:$B$47,MATCH(9,Veri!$L$2:$L$47,0)) -> Çimento Sektöründe Atıkların Prosese, Kaliteye Etkisi ve Enerji Değişimleri Eğitimi | B57: =INDEX(Veri!$J$2:$J$47,MATCH(9,Veri!$L$2:$L$47,0)) -> 36
A58: =INDEX(Veri!$B$2:$B$47,MATCH(10,Veri!$L$2:$L$47,0)) -> Fırın Sisteminde Problem Çözme ve Kök Analizi -Simulasyon Yolu ile | B58: =INDEX(Veri!$J$2:$J$47,MATCH(10,Veri!$L$2:$L$47,0)) -> 36
A66: EN YÜKSEK PUANLI 8 EĞİTİM (5 ÜZERİNDEN)
A68: Eğitim Adı | B68: Değerlendirme Puanı
A69: =INDEX(Veri!$B$2:$B$47,MATCH(1,Veri!$M$2:$M$47,0)) -> Çimento Sektöründe Atıkların Prosese, Kaliteye Etkisi ve Enerji Değişimleri Eğitimi | B69: =INDEX(Veri!$G$2:$G$47,MATCH(1,Veri!$M$2:$M$47,0)) -> 4.51
A70: =INDEX(Veri!$B$2:$B$47,MATCH(2,Veri!$M$2:$M$47,0)) -> Yapay Zeka Kullanım Senaryosu Geliştirme Atölyesi Eğitimi (MEXT İş Birliği ile) | B70: =INDEX(Veri!$G$2:$G$47,MATCH(2,Veri!$M$2:$M$47,0)) -> 4.44
A71: =INDEX(Veri!$B$2:$B$47,MATCH(3,Veri!$M$2:$M$47,0)) -> Genel Metroloji, Uygulamalı Kalibrasyon ve Doğrulama Eğitimi (Çimentaş için) | B71: =INDEX(Veri!$G$2:$G$47,MATCH(3,Veri!$M$2:$M$47,0)) -> 4.43
A72: =INDEX(Veri!$B$2:$B$47,MATCH(4,Veri!$M$2:$M$47,0)) -> Kimyasal Değerlendirme Uzmanı Eğitimi ve Sınavı | B72: =INDEX(Veri!$G$2:$G$47,MATCH(4,Veri!$M$2:$M$47,0)) -> 4.42
A73: =INDEX(Veri!$B$2:$B$47,MATCH(5,Veri!$M$2:$M$47,0)) -> Değişim Yönetimi Eğitimi | B73: =INDEX(Veri!$G$2:$G$47,MATCH(5,Veri!$M$2:$M$47,0)) -> 4.38
A74: =INDEX(Veri!$B$2:$B$47,MATCH(6,Veri!$M$2:$M$47,0)) -> Yeni Mühendisler için Enerji Verimliliği Eğitimi II. Grup | B74: =INDEX(Veri!$G$2:$G$47,MATCH(6,Veri!$M$2:$M$47,0)) -> 4.37
A75: =INDEX(Veri!$B$2:$B$47,MATCH(7,Veri!$M$2:$M$47,0)) -> Kaplumbağa Terbiyecisinin Sırrı (Liderlik) | B75: =INDEX(Veri!$G$2:$G$47,MATCH(7,Veri!$M$2:$M$47,0)) -> 4.31
A76: =INDEX(Veri!$B$2:$B$47,MATCH(8,Veri!$M$2:$M$47,0)) -> Öğütme Verimliliği Eğitimi | B76: =INDEX(Veri!$G$2:$G$47,MATCH(8,Veri!$M$2:$M$47,0)) -> 4.29
...

Sheet Veri
A1: Durum | B1: Eğitim Adı | C1: Gün Sayısı | D1: Tarih | E1: Ay | F1: Eğitim Tipi | G1: Değerlendirme Puanı | H1: Ankete Katılan | I1: Beklenen Kişi Sayısı | J1: Katılan Kişi Sayısı | K1: Sertifika Sayısı | L1: Katılım Sırası | M1: Puan Sırası
A2: PLANLI | B2: Yeni Mühendisler için Enerji Verimliliği Eğitimi | C2: 2 | D2: 7-8 Ocak 2026 | E2: 1 | F2: ÇEVRİM İÇİ | G2: 3.97 | H2: 24 | I2: 25 | J2: 40 | K2: 40 | L2: =RANK(J2,$J$2:$J$47,0)+COUNTIF($J$2:J2,J2)-1 -> 6 | M2: =IF(G2="","",RANK(G2,$G$2:$G$47,0)+COUNTIF($G$2:G2,G2)-1) -> 19
A3: PLANLI | B3: Kapsamiçi Çalışanlar için Enerji Verimliliği ve Çimento Sektörü Uygulamaları Eğitimi | C3: 1 | D3: 1/14/2026 | E3: 1 | F3: ÇEVRİM İÇİ | G3: 4 | H3: 9 | I3: 25 | J3: 26 | K3: 26 | L3: =RANK(J3,$J$2:$J$47,0)+COUNTIF($J$2:J3,J3)-1 -> 13 | M3: =IF(G3="","",RANK(G3,$G$2:$G$47,0)+COUNTIF($G$2:G3,G3)-1) -> 17
A4: PLANLI | B4: C Level Yöneticiler için Siber Güvenlik Eğitimi | C4: 1 | D4: 1/28/2026 | E4: 1 | F4: ÇEVRİM İÇİ | G4: 3.73 | H4: 11 | I4: 15 | J4: 18 | K4: 18 | L4: =RANK(J4,$J$2:$J$47,0)+COUNTIF($J$2:J4,J4)-1 -> 18 | M4: =IF(G4="","",RANK(G4,$G$2:$G$47,0)+COUNTIF($G$2:G4,G4)-1) -> 27
A5: YENİ | B5: Yeni Mühendisler için Enerji Verimliliği Eğitimi II. Grup | C5: 2 | D5: 21-22 Ocak 2026 | E5: 1 | F5: ÇEVRİM İÇİ | G5: 4.37 | H5: 7 | I5: 25 | J5: 16 | K5: 16 | L5: =RANK(J5,$J$2:$J$47,0)+COUNTIF($J$2:J5,J5)-1 -> 21 | M5: =IF(G5="","",RANK(G5,$G$2:$G$47,0)+COUNTIF($G$2:G5,G5)-1) -> 6
A6: PLANLI | B6: Çimento Sektöründe Atıkların Prosese, Kaliteye Etkisi ve Enerji Değişimleri Eğitimi | C6: 2 | D6: 18-19 Şubat 2026 | E6: 2 | F6: SINIF İÇİ | G6: 4.51 | H6: 32 | I6: 25 | J6: 36 | K6: 36 | L6: =RANK(J6,$J$2:$J$47,0)+COUNTIF($J$2:J6,J6)-1 -> 9 | M6: =IF(G6="","",RANK(G6,$G$2:$G$47,0)+COUNTIF($G$2:G6,G6)-1) -> 1
A7: PLANLI | B7: Değişim Yönetimi Eğitimi | C7: 2 | D7: 11-12 Şubat 2026 | E7: 2 | F7: SINIF İÇİ | G7: 4.38 | H7: 11 | I7: 20 | J7: 17 | K7: 17 | L7: =RANK(J7,$J$2:$J$47,0)+COUNTIF($J$2:J7,J7)-1 -> 19 | M7: =IF(G7="","",RANK(G7,$G$2:$G$47,0)+COUNTIF($G$2:G7,G7)-1) -> 5
A8: PLANLI | B8: Modern Satış Yönetimi ve Liderlik Eğitimi | C8: 1 | D8: 2/17/2026 | E8: 2 | F8: SINIF İÇİ | G8: 3.88 | H8: 12 | I8: 15 | J8: 17 | K8: 17 | L8: =RANK(J8,$J$2:$J$47,0)+COUNTIF($J$2:J8,J8)-1 -> 20 | M8: =IF(G8="","",RANK(G8,$G$2:$G$47,0)+COUNTIF($G$2:G8,G8)-1) -> 20
A9: PLANLI | B9: Phyton Temel Düzey Eğitimi | C9: 5 | D9: 23-27 Şubat 2026 | E9: 2 | F9: SINIF İÇİ | I9: 15 | J9: 13 | K9: 13 | L9: =RANK(J9,$J$2:$J$47,0)+COUNTIF($J$2:J9,J9)-1 -> 24 | M9: =IF(G9="","",RANK(G9,$G$2:$G$47,0)+COUNTIF($G$2:G9,G9)-1)
A10: PLANLI | B10: Enerji Yöneticisi Kursu | C10: 11 | D10: 9-20 Şubat 2026 | E10: 2 | F10: SINIF İÇİ | J10: 7 | K10: 7 | L10: =RANK(J10,$J$2:$J$47,0)+COUNTIF($J$2:J10,J10)-1 -> 37 | M10: =IF(G10="","",RANK(G10,$G$2:$G$47,0)+COUNTIF($G$2:G10,G10)-1)
A11: YENİ | B11: Yeşil Hidrojen ve Çimento Sektörü Webinar Serisi I | C11: 1 | D11: 3/12/2026 | E11: 3 | F11: ÇEVRİM İÇİ | J11: 187 | K11: 187 | L11: =RANK(J11,$J$2:$J$47,0)+COUNTIF($J$2:J11,J11)-1 -> 1 | M11: =IF(G11="","",RANK(G11,$G$2:$G$47,0)+COUNTIF($G$2:G11,G11)-1)
A12: PLANLI | B12: Su Ayak İzi Hesaplama Eğitimi | C12: 2 | D12: 5-6 Mart 2026 | E12: 3 | F12: SINIF İÇİ | G12: 4.13 | H12: 18 | I12: 25 | J12: 21 | K12: 21 | L12: =RANK(J12,$J$2:$J$47,0)+COUNTIF($J$2:J12,J12)-1 -> 16 | M12: =IF(G12="","",RANK(G12,$G$2:$G$47,0)+COUNTIF($G$2:G12,G12)-1) -> 13
A13: PLANLI | B13: Süreç Yönetimi Tabanlı Kurumsal Dönüşüm Eğitimi | C13: 2 | D13: 12-13 Mart 2026 | E13: 3 | F13: ÇEVRİM İÇİ | I13: 20 | J13: 13 | K13: 13 | L13: =RANK(J13,$J$2:$J$47,0)+COUNTIF($J$2:J13,J13)-1 -> 25 | M13: =IF(G13="","",RANK(G13,$G$2:$G$47,0)+COUNTIF($G$2:G13,G13)-1)
A14: YENİ | B14: Genel Metroloji, Uygulamalı Kalibrasyon ve Doğrulama Eğitimi (Çimentaş için) | C14: 2 | D14: 24-25 Mart 2026 | E14: 3 | F14: SINIF İÇİ | G14: 4.43 | H14: 9 | J14: 9 | K14: 9 | L14: =RANK(J14,$J$2:$J$47,0)+COUNTIF($J$2:J14,J14)-1 -> 30 | M14: =IF(G14="","",RANK(G14,$G$2:$G$47,0)+COUNTIF($G$2:G14,G14)-1) -> 3
A15: PLANLI | B15: Phyton İleri Düzey Eğitimi | C15: 3 | D15: 1-3 Nisan 2026 | E15: 4 | F15: SINIF İÇİ | I15: 15 | J15: 10 | K15: 10 | L15: =RANK(J15,$J$2:$J$47,0)+COUNTIF($J$2:J15,J15)-1 -> 29 | M15: =IF(G15="","",RANK(G15,$G$2:$G$47,0)+COUNTIF($G$2:G15,G15)-1)
A16: PLANLI | B16: Karbon Ayak İzi Hesaplama / Raporlama Eğitimi | C16: 2 | D16: 7-8 Nisan 2026 | E16: 4 | F16: SINIF İÇİ | G16: 3.61 | H16: 13 | I16: 20 | J16: 22 | K16: 22 | L16: =RANK(J16,$J$2:$J$47,0)+COUNTIF($J$2:J16,J16)-1 -> 15 | M16: =IF(G16="","",RANK(G16,$G$2:$G$47,0)+COUNTIF($G$2:G16,G16)-1) -> 28
A17: PLANLI | B17: Uygulamalı Kömür Numune ve Analiz Eğitimi | C17: 1 | D17: 4/8/2026 | E17: 4 | F17: SINIF İÇİ | I17: 10 | J17: 7 | K17: 7 | L17: =RANK(J17,$J$2:$J$47,0)+COUNTIF($J$2:J17,J17)-1 -> 38 | M17: =IF(G17="","",RANK(G17,$G$2:$G$47,0)+COUNTIF($G$2:G17,G17)-1)
A18: PLANLI | B18: Öğütme Verimliliği Eğitimi | C18: 2 | D18: 7-8 Nisan 2026 | E18: 4 | F18: SINIF İÇİ | G18: 4.29 | H18: 19 | I18: 25 | J18: 32 | K18: 32 | L18: =RANK(J18,$J$2:$J$47,0)+COUNTIF($J$2:J18,J18)-1 -> 11 | M18: =IF(G18="","",RANK(G18,$G$2:$G$47,0)+COUNTIF($G$2:G18,G18)-1) -> 8
A19: PLANLI | B19: Kaplumbağa Terbiyecisinin Sırrı (Liderlik) | C19: 1 | D19: 4/21/2026 | E19: 4 | F19: SINIF İÇİ | G19: 4.31 | H19: 13 | I19: 15 | J19: 9 | K19: 9 | L19: =RANK(J19,$J$2:$J$47,0)+COUNTIF($J$2:J19,J19)-1 -> 31 | M19: =IF(G19="","",RANK(G19,$G$2:$G$47,0)+COUNTIF($G$2:G19,G19)-1) -> 7
A20: PLANLI | B20: Kimyasal Değerlendirme Uzmanı Eğitimi ve Sınavı | C20: 9 | D20: 4-13 Mayıs 2026 | E20: 5 | F20: SINIF İÇİ | G20: 4.42 | H20: 5 | I20: 25 | J20: 15 | K20: 15 | L20: =RANK(J20,$J$2:$J$47,0)+COUNTIF($J$2:J20,J20)-1 -> 22 | M20: =IF(G20="","",RANK(G20,$G$2:$G$47,0)+COUNTIF($G$2:G20,G20)-1) -> 4
A21: PLANLI | B21: Makinalarda Duruma Dayalı Bakım (CBM) Kararlarında | C21: 2 | D21: 16-17 Nisan 2026 | E21: 4 | F21: ÇEVRİM İÇİ | G21: 3.81 | H21: 15 | I21: 30 | J21: 29 | K21: 29 | L21: =RANK(J21,$J$2:$J$47,0)+COUNTIF($J$2:J21,J21)-1 -> 12 | M21: =IF(G21="","",RANK(G21,$G$2:$G$47,0)+COUNTIF($G$2:G21,G21)-1) -> 24
A22: PLANLI | B22: Çimento Sektörü Özelinde Sınırda Karbon Düzenleme Mekanizması Eğitimi | C22: 2 | D22: 16-17 Nisan 2026 | E22: 4 | F22: SINIF İÇİ | G22: 3.41 | H22: 8 | I22: 30 | J22: 37 | K22: 37 | L22: =RANK(J22,$J$2:$J$47,0)+COUNTIF($J$2:J22,J22)-1 -> 8 | M22: =IF(G22="","",RANK(G22,$G$2:$G$47,0)+COUNTIF($G$2:G22,G22)-1) -> 30
A23: PLANLI | B23: Yazılı İletişimde Algı Yönetimi ve Raporlama Eğitimi | C23: 1 | D23: 4/13/2026 | E23: 4 | F23: SINIF İÇİ | G23: 4.28 | H23: 9 | I23: 15 | J23: 12 | K23: 12 | L23: =RANK(J23,$J$2:$J$47,0)+COUNTIF($J$2:J23,J23)-1 -> 26 | M23: =IF(G23="","",RANK(G23,$G$2:$G$47,0)+COUNTIF($G$2:G23,G23)-1) -> 9
A24: PLANLI | B24: Pyroprocess Eğitimi | C24: 2 | D24: 5-6 Mayıs 2026 | E24: 5 | F24: SINIF İÇİ | G24: 3.77 | H24: 11 | I24: 25 | J24: 26 | K24: 26 | L24: =RANK(J24,$J$2:$J$47,0)+COUNTIF($J$2:J24,J24)-1 -> 14 | M24: =IF(G24="","",RANK(G24,$G$2:$G$47,0)+COUNTIF($G$2:G24,G24)-1) -> 25
A25: YENİ | B25: İş Süreçlerinde Akıllı Dönüşüm: Veri ve Yapay Zeka (MEXT İş Birliği ile) | C25: 1 | D25: 4/28/2026 | E25: 4 | F25: ÇEVRİM İÇİ | G25: 4.22 | H25: 8 | J25: 11 | K25: 11 | L25: =RANK(J25,$J$2:$J$47,0)+COUNTIF($J$2:J25,J25)-1 -> 27 | M25: =IF(G25="","",RANK(G25,$G$2:$G$47,0)+COUNTIF($G$2:G25,G25)-1) -> 11
A26: YENİ | B26: Düşük Karbon Yolunda Yeni Nesil Çimentolar Zirvesi | C26: 1 | D26: 4/28/2026 | E26: 4 | F26: SINIF İÇİ | G26: 3.88 | H26: 26 | J26: 83 | K26: 83 | L26: =RANK(J26,$J$2:$J$47,0)+COUNTIF($J$2:J26,J26)-1 -> 3 | M26: =IF(G26="","",RANK(G26,$G$2:$G$47,0)+COUNTIF($G$2:G26,G26)-1) -> 21
A27: YENİ | B27: Yeşil Hidrojen ve Çimento Sektörü Webinar Serisi II | C27: 1 | D27: 4/29/2026 | E27: 4 | F27: ÇEVRİM İÇİ | J27: 138 | K27: 138 | L27: =RANK(J27,$J$2:$J$47,0)+COUNTIF($J$2:J27,J27)-1 -> 2 | M27: =IF(G27="","",RANK(G27,$G$2:$G$47,0)+COUNTIF($G$2:G27,G27)-1)
A28: PLANLI | B28: Temel Seviye Hidrolik- Elektrohidrolik Eğitimi | C28: 5 | D28: 4-8 Mayıs 2026 | E28: 5 | F28: SINIF İÇİ | I28: 25 | J28: 9 | K28: 9 | L28: =RANK(J28,$J$2:$J$47,0)+COUNTIF($J$2:J28,J28)-1 -> 32 | M28: =IF(G28="","",RANK(G28,$G$2:$G$47,0)+COUNTIF($G$2:G28,G28)-1)
A29: YENİ | B29: LCA Eğitimi | C29: 2 | D29: 14-15 Mayıs 2026 | E29: 5 | F29: SINIF İÇİ | G29: 4.14 | H29: 6 | J29: 14 | K29: 14 | L29: =RANK(J29,$J$2:$J$47,0)+COUNTIF($J$2:J29,J29)-1 -> 23 | M29: =IF(G29="","",RANK(G29,$G$2:$G$47,0)+COUNTIF($G$2:G29,G29)-1) -> 12
A30: PLANLI | B30: Sürdürülebilir Tedarik Zinciri Yönetimi Eğitimi | C30: 2 | D30: 29-30 Nisan 2026 | E30: 4 | F30: ÇEVRİM İÇİ | G30: 3.77 | H30: 20 | I30: 20 | J30: 40 | K30: 40 | L30: =RANK(J30,$J$2:$J$47,0)+COUNTIF($J$2:J30,J30)-1 -> 7 | M30: =IF(G30="","",RANK(G30,$G$2:$G$47,0)+COUNTIF($G$2:G30,G30)-1) -> 26
A31: YENİ | B31: Uygulamalı Kömür Numune ve Analiz Eğitimi II. Grup | C31: 1 | D31: 5/6/2026 | E31: 5 | F31: SINIF İÇİ | J31: 7 | K31: 7 | L31: =RANK(J31,$J$2:$J$47,0)+COUNTIF($J$2:J31,J31)-1 -> 39 | M31: =IF(G31="","",RANK(G31,$G$2:$G$47,0)+COUNTIF($G$2:G31,G31)-1)
A32: YENİ | B32: Uygulamalı Çimento Analizleri Eğitimi I. Grup | C32: 1 | D32: 5/7/2026 | E32: 5 | F32: SINIF İÇİ | I32: 10 | J32: 7 | K32: 7 | L32: =RANK(J32,$J$2:$J$47,0)+COUNTIF($J$2:J32,J32)-1 -> 40 | M32: =IF(G32="","",RANK(G32,$G$2:$G$47,0)+COUNTIF($G$2:G32,G32)-1)
A33: YENİ | B33: Yapay Zeka Çağında Veri Odaklı Liderlik Eğitimi (MEXT İş Birliği ile) | C33: 1 | D33: 5/11/2026 | E33: 5 | F33: ÇEVRİM İÇİ | G33: 4.03 | H33: 17 | J33: 21 | K33: 21 | L33: =RANK(J33,$J$2:$J$47,0)+COUNTIF($J$2:J33,J33)-1 -> 17 | M33: =IF(G33="","",RANK(G33,$G$2:$G$47,0)+COUNTIF($G$2:G33,G33)-1) -> 15
A34: PLANLI | B34: Fırın Sisteminde Problem Çözme ve Kök Analizi -Simulasyon Yolu ile | C34: 2 | D34: 13-14 Mayıs 2026 | E34: 5 | F34: ÇEVRİM İÇİ | G34: 4.23 | H34: 17 | I34: 25 | J34: 36 | K34: 36 | L34: =RANK(J34,$J$2:$J$47,0)+COUNTIF($J$2:J34,J34)-1 -> 10 | M34: =IF(G34="","",RANK(G34,$G$2:$G$47,0)+COUNTIF($G$2:G34,G34)-1) -> 10
A35: YENİ | B35: Uygulamalı Çimento Analizleri Eğitimi II. Grup | C35: 1 | D35: 5/14/2026 | E35: 5 | F35: SINIF İÇİ | G35: 3.47 | H35: 5 | J35: 9 | K35: 9 | L35: =RANK(J35,$J$2:$J$47,0)+COUNTIF($J$2:J35,J35)-1 -> 33 | M35: =IF(G35="","",RANK(G35,$G$2:$G$47,0)+COUNTIF($G$2:G35,G35)-1) -> 29
A36: YENİ | B36: Uygulamalı Çimento Analizleri Eğitimi III.Grup | C36: 1 | D36: 5/21/2026 | E36: 5 | F36: SINIF İÇİ | G36: 4.11 | H36: 2 | J36: 8 | K36: 8 | L36: =RANK(J36,$J$2:$J$47,0)+COUNTIF($J$2:J36,J36)-1 -> 34 | M36: =IF(G36="","",RANK(G36,$G$2:$G$47,0)+COUNTIF($G$2:G36,G36)-1) -> 14
A37: YENİ | B37: Yeşil Hidrojen ve Çimento Sektörü Webinar Serisi III | C37: 1 | D37: 5/21/2026 | E37: 5 | F37: ÇEVRİM İÇİ | J37: 82 | K37: 82 | L37: =RANK(J37,$J$2:$J$47,0)+COUNTIF($J$2:J37,J37)-1 -> 4 | M37: =IF(G37="","",RANK(G37,$G$2:$G$47,0)+COUNTIF($G$2:G37,G37)-1)
A38: PLANLI | B38: İleri Seviye Hidrolik- Elektrohidrolik Eğitimi | C38: 3 | D38: 10-12 Haziran 2026 | E38: 6 | F38: SINIF İÇİ | J38: 8 | K38: 8 | L38: =RANK(J38,$J$2:$J$47,0)+COUNTIF($J$2:J38,J38)-1 -> 35 | M38: =IF(G38="","",RANK(G38,$G$2:$G$47,0)+COUNTIF($G$2:G38,G38)-1)
A39: YENİ | B39: Yapay Zeka Kullanım Senaryosu Geliştirme Atölyesi Eğitimi (MEXT İş Birliği ile) | C39: 2 | D39: 9-10 Haziran 2026 | E39: 6 | F39: SINIF İÇİ | G39: 4.44 | H39: 4 | J39: 11 | K39: 11 | L39: =RANK(J39,$J$2:$J$47,0)+COUNTIF($J$2:J39,J39)-1 -> 28 | M39: =IF(G39="","",RANK(G39,$G$2:$G$47,0)+COUNTIF($G$2:G39,G39)-1) -> 2
A40: YENİ | B40: Uygulamalı Atık Numune Hazırlama ve Analiz Eğitimi | C40: 1 | D40: 6/11/2026 | E40: 6 | F40: SINIF İÇİ | G40: 3.87 | H40: 5 | J40: 8 | K40: 8 | L40: =RANK(J40,$J$2:$J$47,0)+COUNTIF($J$2:J40,J40)-1 -> 36 | M40: =IF(G40="","",RANK(G40,$G$2:$G$47,0)+COUNTIF($G$2:G40,G40)-1) -> 23
...
